Workbook
Name FirstDownDiff: Reference!$A$8:$B$12
Name FirstDownDiff2: Reference2!$A$6:$B$8
Name PassYardsDiff: Reference!$G$8:$H$12
Name PassYardsDiff2: Reference2!$G$6:$H$8
Name RushYards2: Reference2!$J$6:$K$8
Name RushYardsDiff: Reference!$J$8:$K$12
Name TotalYardDiff2: Reference2!$D$6:$E$8
Name TotalYardsDiff: Reference!$D$8:$E$12
Name TurnOverDiff: Reference!$M$8:$N$12
Name TurnOverDiff2: Reference2!$M$6:$N$8

Sheet Raw
C1: 1stD | D1: TotYd | E1: PassY | F1: RushY | G1: TO | H1: 1stD | I1: TotYd | J1: PassY | K1: RushY | L1: TO
A2: L | B2: @ | C2: 15 | D2: 349 | E2: 329 | F2: 20 | H2: 26 | I2: 440 | J2: 258 | K2: 182
A3: L | C3: 21 | D3: 248 | E3: 127 | F3: 121 | G3: 2 | H3: 21 | I3: 413 | J3: 240 | K3: 173 | L3: 1
A4: L | C4: 20 | D4: 321 | E4: 206 | F4: 115 | G4: 1 | H4: 21 | I4: 340 | J4: 225 | K4: 115
A5: W | B5: @ | C5: 26 | D5: 514 | E5: 248 | F5: 266 | H5: 21 | I5: 370 | J5: 262 | K5: 108
A6: W | C6: 24 | D6: 442 | E6: 340 | F6: 102 | H6: 31 | I6: 444 | J6: 341 | K6: 103
A7: W | B7: @ | C7: 18 | D7: 245 | E7: 89 | F7: 156 | H7: 21 | I7: 263 | J7: 156 | K7: 107 | L7: 3
A8: L | B8: @ | C8: 10 | D8: 237 | E8: 197 | F8: 40 | H8: 28 | I8: 510 | J8: 373 | K8: 137 | L8: 1
A9: L | C9: 19 | D9: 357 | E9: 204 | F9: 153 | H9: 21 | I9: 411 | J9: 310 | K9: 101
A10: L | B10: @ | C10: 20 | D10: 417 | E10: 342 | F10: 75 | G10: 2 | H10: 26 | I10: 457 | J10: 339 | K10: 118 | L10: 3
A11: L | B11: @ | C11: 21 | D11: 266 | E11: 131 | F11: 135 | G11: 2 | H11: 26 | I11: 442 | J11: 408 | K11: 34 | L11: 2
A12: L | C12: 13 | D12: 198 | E12: 124 | F12: 74 | G12: 1 | H12: 27 | I12: 549 | J12: 417 | K12: 132
A13: L | C13: 17 | D13: 236 | E13: 165 | F13: 71 | G13: 3 | H13: 20 | I13: 275 | J13: 135 | K13: 140 | L13: 2
A14: W | C14: 26 | D14: 445 | E14: 219 | F14: 226 | G14: 1 | H14: 25 | I14: 393 | J14: 241 | K14: 152 | L14: 2
A15: W | B15: @ | C15: 21 | D15: 412 | E15: 159 | F15: 253 | H15: 13 | I15: 224 | J15: 133 | K15: 91 | L15: 1
A16: L | B16: @ | C16: 22 | D16: 393 | E16: 322 | F16: 71 | G16: 5 | H16: 25 | I16: 424 | J16: 311 | K16: 113
A17: L | B17: @ | C17: 27 | D17: 345 | E17: 272 | F17: 73 | G17: 3 | H17: 18 | I17: 269 | J17: 97 | K17: 172
A18: W | C18: 19 | D18: 367 | E18: 310 | F18: 57 | G18: 3 | H18: 18 | I18: 286 | J18: 237 | K18: 49 | L18: 3
A19: L | B19: @ | C19: 25 | D19: 397 | E19: 304 | F19: 93 | G19: 1 | H19: 29 | I19: 379 | J19: 300 | K19: 79
A20: L | C20: 24 | D20: 422 | E20: 364 | F20: 58 | G20: 1 | H20: 22 | I20: 365 | J20: 227 | K20: 138
A21: L | B21: @ | C21: 22 | D21: 373 | E21: 316 | F21: 57 | G21: 1 | H21: 31 | I21: 592 | J21: 426 | K21: 166 | L21: 1
A22: L | B22: @ | C22: 31 | D22: 444 | E22: 341 | F22: 103 | H22: 24 | I22: 442 | J22: 340 | K22: 102
A23: L | C23: 14 | D23: 224 | E23: 186 | F23: 38 | G23: 3 | H23: 23 | I23: 381 | J23: 291 | K23: 90
A24: L | C24: 30 | D24: 510 | E24: 441 | F24: 69 | G24: 3 | H24: 18 | I24: 322 | J24: 171 | K24: 151
A25: W | B25: @ | C25: 24 | D25: 317 | E25: 174 | F25: 143 | G25: 1 | H25: 18 | I25: 310 | J25: 258 | K25: 52
A26: W | B26: @ | C26: 20 | D26: 349 | E26: 295 | F26: 54 | H26: 17 | I26: 347 | J26: 270 | K26: 77 | L26: 4
A27: L | C27: 22 | D27: 337 | E27: 280 | F27: 57 | G27: 2 | H27: 20 | I27: 446 | J27: 313 | K27: 133 | L27: 2
A28: L | C28: 27 | D28: 348 | E28: 259 | F28: 89 | G28: 3 | H28: 14 | I28: 279 | J28: 184 | K28: 95
A29: W | C29: 22 | D29: 461 | E29: 302 | F29: 159 | H29: 27 | I29: 345 | J29: 245 | K29: 100 | L29: 4
A30: W | B30: @ | C30: 20 | D30: 290 | E30: 201 | F30: 89 | G30: 1 | H30: 20 | I30: 313 | J30: 193 | K30: 120 | L30: 2
A31: W | C31: 28 | D31: 518 | E31: 383 | F31: 135 | G31: 2 | H31: 17 | I31: 288 | J31: 173 | K31: 115 | L31: 1
A32: W | B32: @ | C32: 28 | D32: 373 | E32: 286 | F32: 87 | G32: 1 | H32: 14 | I32: 329 | J32: 193 | K32: 136 | L32: 3
A33: W | B33: @ | C33: 31 | D33: 643 | E33: 378 | F33: 265 | H33: 12 | I33: 200 | J33: 179 | K33: 21 | L33: 3
A34: W | C34: 26 | D34: 440 | E34: 258 | F34: 182 | H34: 15 | I34: 349 | J34: 329 | K34: 20
A35: L | B35: @ | C35: 29 | D35: 452 | E35: 249 | F35: 203 | H35: 27 | I35: 503 | J35: 363 | K35: 140
A36: L | C36: 24 | D36: 395 | E36: 222 | F36: 173 | G36: 3 | H36: 22 | I36: 530 | J36: 337 | K36: 193 | L36: 1
A37: W | B37: @ | C37: 22 | D37: 277 | E37: 139 | F37: 138 | G37: 3 | H37: 18 | I37: 269 | J37: 192 | K37: 77 | L37: 2
A38: W | C38: 26 | D38: 497 | E38: 228 | F38: 269 | G38: 1 | H38: 18 | I38: 250 | J38: 217 | K38: 33 | L38: 1
A39: W | B39: @ | C39: 14 | D39: 340 | E39: 141 | F39: 199 | H39: 20 | I39: 347 | J39: 241 | K39: 106 | L39: 2
A40: W | C40: 26 | D40: 372 | E40: 162 | F40: 210 | G40: 2 | H40: 22 | I40: 342 | J40: 268 | K40: 74 | L40: 2
...

Sheet Clean
A1: Where | B1: 1stD H | C1: TotYd H | D1: PassY H | E1: RushY H | F1: TO H | G1: 1stD A | H1: TotYd A | I1: PassY A | J1: RushY A | K1: TO A | L1: 1stD Diff | M1: TotYd Diff | N1: PassY Diff | O1: RushY Diff | P1: TO Diff | Q1: Outcome
A2: A | B2: 15 | C2: 349 | D2: 329 | E2: 20 | F2: 0 | G2: 26 | H2: 440 | I2: 258 | J2: 182 | K2: 0 | L2: =B2-G2 -> -11 | M2: =C2-H2 -> -91 | N2: =D2-I2 -> 71 | O2: =E2-J2 -> -162 | P2: =F2-K2 -> 0 | Q2: L
A3: H | B3: 21 | C3: 248 | D3: 127 | E3: 121 | F3: 2 | G3: 21 | H3: 413 | I3: 240 | J3: 173 | K3: 1 | L3: =B3-G3 -> 0 | M3: =C3-H3 -> -165 | N3: =D3-I3 -> -113 | O3: =E3-J3 -> -52 | P3: =F3-K3 -> 1 | Q3: L
A4: H | B4: 20 | C4: 321 | D4: 206 | E4: 115 | F4: 1 | G4: 21 | H4: 340 | I4: 225 | J4: 115 | K4: 0 | L4: =B4-G4 -> -1 | M4: =C4-H4 -> -19 | N4: =D4-I4 -> -19 | O4: =E4-J4 -> 0 | P4: =F4-K4 -> 1 | Q4: L
A5: A | B5: 26 | C5: 514 | D5: 248 | E5: 266 | F5: 0 | G5: 21 | H5: 370 | I5: 262 | J5: 108 | K5: 0 | L5: =B5-G5 -> 5 | M5: =C5-H5 -> 144 | N5: =D5-I5 -> -14 | O5: =E5-J5 -> 158 | P5: =F5-K5 -> 0 | Q5: W
A6: H | B6: 24 | C6: 442 | D6: 340 | E6: 102 | F6: 0 | G6: 31 | H6: 444 | I6: 341 | J6: 103 | K6: 0 | L6: =B6-G6 -> -7 | M6: =C6-H6 -> -2 | N6: =D6-I6 -> -1 | O6: =E6-J6 -> -1 | P6: =F6-K6 -> 0 | Q6: W
A7: A | B7: 18 | C7: 245 | D7: 89 | E7: 156 | F7: 0 | G7: 21 | H7: 263 | I7: 156 | J7: 107 | K7: 3 | L7: =B7-G7 -> -3 | M7: =C7-H7 -> -18 | N7: =D7-I7 -> -67 | O7: =E7-J7 -> 49 | P7: =F7-K7 -> -3 | Q7: W
A8: A | B8: 10 | C8: 237 | D8: 197 | E8: 40 | F8: 0 | G8: 28 | H8: 510 | I8: 373 | J8: 137 | K8: 1 | L8: =B8-G8 -> -18 | M8: =C8-H8 -> -273 | N8: =D8-I8 -> -176 | O8: =E8-J8 -> -97 | P8: =F8-K8 -> -1 | Q8: L
A9: H | B9: 19 | C9: 357 | D9: 204 | E9: 153 | F9: 0 | G9: 21 | H9: 411 | I9: 310 | J9: 101 | K9: 0 | L9: =B9-G9 -> -2 | M9: =C9-H9 -> -54 | N9: =D9-I9 -> -106 | O9: =E9-J9 -> 52 | P9: =F9-K9 -> 0 | Q9: L
A10: A | B10: 20 | C10: 417 | D10: 342 | E10: 75 | F10: 2 | G10: 26 | H10: 457 | I10: 339 | J10: 118 | K10: 3 | L10: =B10-G10 -> -6 | M10: =C10-H10 -> -40 | N10: =D10-I10 -> 3 | O10: =E10-J10 -> -43 | P10: =F10-K10 -> -1 | Q10: L
A11: A | B11: 21 | C11: 266 | D11: 131 | E11: 135 | F11: 2 | G11: 26 | H11: 442 | I11: 408 | J11: 34 | K11: 2 | L11: =B11-G11 -> -5 | M11: =C11-H11 -> -176 | N11: =D11-I11 -> -277 | O11: =E11-J11 -> 101 | P11: =F11-K11 -> 0 | Q11: L
A12: H | B12: 13 | C12: 198 | D12: 124 | E12: 74 | F12: 1 | G12: 27 | H12: 549 | I12: 417 | J12: 132 | K12: 0 | L12: =B12-G12 -> -14 | M12: =C12-H12 -> -351 | N12: =D12-I12 -> -293 | O12: =E12-J12 -> -58 | P12: =F12-K12 -> 1 | Q12: L
A13: H | B13: 17 | C13: 236 | D13: 165 | E13: 71 | F13: 3 | G13: 20 | H13: 275 | I13: 135 | J13: 140 | K13: 2 | L13: =B13-G13 -> -3 | M13: =C13-H13 -> -39 | N13: =D13-I13 -> 30 | O13: =E13-J13 -> -69 | P13: =F13-K13 -> 1 | Q13: L
... A533: A | B533: 13 | C533: 271 | D533: 183 | E533: 88 | F533: 2 | G533: 22 | H533: 517 | I533: 294 | J533: 223 | K533: 1 | L533: =B533-G533 -> -9 | M533: =C533-H533 -> -246 | N533: =D533-I533 -> -111 | O533: =E533-J533 -> -135 | P533: =F533-K533 -> 1 | Q533: L

Sheet Randomized
A1: Where | B1: 1stD H | C1: TotYd H | D1: PassY H | E1: RushY H | F1: TO H | G1: 1stD A | H1: TotYd A | I1: PassY A | J1: RushY A | K1: TO A | L1: 1stD Diff | M1: TotYd Diff | N1: PassY Diff | O1: RushY Diff | P1: TO Diff | Q1: Outcome
A2: H | B2: 25 | C2: 491 | D2: 235 | E2: 256 | F2: 0 | G2: 16 | H2: 232 | I2: 110 | J2: 122 | K2: 2 | L2: =B2-G2 -> 9 | M2: =C2-H2 -> 259 | N2: =D2-I2 -> 125 | O2: =E2-J2 -> 134 | P2: =F2-K2 -> -2 | Q2: W
A3: A | B3: 16 | C3: 175 | D3: 102 | E3: 73 | F3: 2 | G3: 20 | H3: 326 | I3: 260 | J3: 66 | K3: 1 | L3: =B3-G3 -> -4 | M3: =C3-H3 -> -151 | N3: =D3-I3 -> -158 | O3: =E3-J3 -> 7 | P3: =F3-K3 -> 1 | Q3: L
A4: H | B4: 21 | C4: 381 | D4: 313 | E4: 68 | F4: 2 | G4: 6 | H4: 105 | I4: 69 | J4: 36 | K4: 1 | L4: =B4-G4 -> 15 | M4: =C4-H4 -> 276 | N4: =D4-I4 -> 244 | O4: =E4-J4 -> 32 | P4: =F4-K4 -> 1 | Q4: W
A5: A | B5: 29 | C5: 418 | D5: 319 | E5: 99 | F5: 1 | G5: 31 | H5: 492 | I5: 347 | J5: 145 | K5: 1 | L5: =B5-G5 -> -2 | M5: =C5-H5 -> -74 | N5: =D5-I5 -> -28 | O5: =E5-J5 -> -46 | P5: =F5-K5 -> 0 | Q5: L
A6: A | B6: 23 | C6: 381 | D6: 291 | E6: 90 | F6: 0 | G6: 14 | H6: 224 | I6: 186 | J6: 38 | K6: 3 | L6: =B6-G6 -> 9 | M6: =C6-H6 -> 157 | N6: =D6-I6 -> 105 | O6: =E6-J6 -> 52 | P6: =F6-K6 -> -3 | Q6: W
A7: H | B7: 26 | C7: 497 | D7: 228 | E7: 269 | F7: 1 | G7: 18 | H7: 250 | I7: 217 | J7: 33 | K7: 1 | L7: =B7-G7 -> 8 | M7: =C7-H7 -> 247 | N7: =D7-I7 -> 11 | O7: =E7-J7 -> 236 | P7: =F7-K7 -> 0 | Q7: W
A8: A | B8: 10 | C8: 168 | D8: 77 | E8: 91 | F8: 2 | G8: 19 | H8: 304 | I8: 81 | J8: 223 | K8: 2 | L8: =B8-G8 -> -9 | M8: =C8-H8 -> -136 | N8: =D8-I8 -> -4 | O8: =E8-J8 -> -132 | P8: =F8-K8 -> 0 | Q8: L
A9: H | B9: 25 | C9: 510 | D9: 362 | E9: 148 | F9: 1 | G9: 22 | H9: 414 | I9: 234 | J9: 180 | K9: 1 | L9: =B9-G9 -> 3 | M9: =C9-H9 -> 96 | N9: =D9-I9 -> 128 | O9: =E9-J9 -> -32 | P9: =F9-K9 -> 0 | Q9: W
A10: A | B10: 31 | C10: 444 | D10: 341 | E10: 103 | F10: 0 | G10: 24 | H10: 442 | I10: 340 | J10: 102 | K10: 0 | L10: =B10-G10 -> 7 | M10: =C10-H10 -> 2 | N10: =D10-I10 -> 1 | O10: =E10-J10 -> 1 | P10: =F10-K10 -> 0 | Q10: L
A11: H | B11: 18 | C11: 277 | D11: 233 | E11: 44 | F11: 0 | G11: 15 | H11: 271 | I11: 209 | J11: 62 | K11: 0 | L11: =B11-G11 -> 3 | M11: =C11-H11 -> 6 | N11: =D11-I11 -> 24 | O11: =E11-J11 -> -18 | P11: =F11-K11 -> 0 | Q11: W
A12: A | B12: 15 | C12: 378 | D12: 285 | E12: 93 | F12: 0 | G12: 29 | H12: 388 | I12: 258 | J12: 130 | K12: 0 | L12: =B12-G12 -> -14 | M12: =C12-H12 -> -10 | N12: =D12-I12 -> 27 | O12: =E12-J12 -> -37 | P12: =F12-K12 -> 0 | Q12: L
A13: H | B13: 12 | C13: 232 | D13: 160 | E13: 72 | F13: 1 | G13: 22 | H13: 429 | I13: 395 | J13: 34 | K13: 3 | L13: =B13-G13 -> -10 | M13: =C13-H13 -> -197 | N13: =D13-I13 -> -235 | O13: =E13-J13 -> 38 | P13: =F13-K13 -> -2 | Q13: W
... A533: H | B533: 23 | C533: 385 | D533: 174 | E533: 211 | F533: 0 | G533: 17 | H533: 302 | I533: 214 | J533: 88 | K533: 1 | L533: =B533-G533 -> 6 | M533: =C533-H533 -> 83 | N533: =D533-I533 -> -40 | O533: =E533-J533 -> 123 | P533: =F533-K533 -> -1 | Q533: W

Sheet NFLDataSet
A1: Where | B1: 1stD Diff | C1: TotYd Diff | D1: PassY Diff | E1: RushY Diff | F1: TO Diff | G1: Outcome
A2: H | B2: 9 | C2: 259 | D2: 125 | E2: 134 | F2: -2 | G2: W
A3: A | B3: -4 | C3: -151 | D3: -158 | E3: 7 | F3: 1 | G3: L
A4: H | B4: 15 | C4: 276 | D4: 244 | E4: 32 | F4: 1 | G4: W
A5: A | B5: -2 | C5: -74 | D5: -28 | E5: -46 | F5: 0 | G5: L
A6: A | B6: 9 | C6: 157 | D6: 105 | E6: 52 | F6: -3 | G6: W
A7: H | B7: 8 | C7: 247 | D7: 11 | E7: 236 | F7: 0 | G7: W
A8: A | B8: -9 | C8: -136 | D8: -4 | E8: -132 | F8: 0 | G8: L
A9: H | B9: 3 | C9: 96 | D9: 128 | E9: -32 | F9: 0 | G9: W
A10: A | B10: 7 | C10: 2 | D10: 1 | E10: 1 | F10: 0 | G10: L
A11: H | B11: 3 | C11: 6 | D11: 24 | E11: -18 | F11: 0 | G11: W
A12: A | B12: -14 | C12: -10 | D12: 27 | E12: -37 | F12: 0 | G12: L
A13: H | B13: -10 | C13: -197 | D13: -235 | E13: 38 | F13: -2 | G13: W
... A425: H | B425: -19 | C425: -443 | D425: -199 | E425: -244 | F425: 3 | G425: L
A426: H | B426: -5 | C426: -118 | D426: 2 | E426: -120 | F426: 0 | G426: L | H426: xxxxxxxx
A427: A | B427: 6 | C427: 147 | D427: 87 | E427: 60 | F427: 3 | G427: W
A428: H | B428: 7 | C428: 47 | D428: 33 | E428: 14 | F428: -1 | G428: W
A429: H | B429: -8 | C429: -134 | D429: -45 | E429: -89 | F429: -2 | G429: W
A430: A | B430: 2 | C430: -7 | D430: -28 | E430: 21 | F430: -3 | G430: W
A431: H | B431: -5 | C431: -166 | D431: -30 | E431: -136 | F431: 1 | G431: L
A432: H | B432: -2 | C432: -4 | D432: -227 | E432: 223 | F432: -3 | G432: W
A433: A | B433: 7 | C433: 116 | D433: 111 | E433: 5 | F433: 0 | G433: W
A434: A | B434: -12 | C434: -158 | D434: -56 | E434: -102 | F434: 2 | G434: L
A435: H | B435: -6 | C435: -3 | D435: -4 | E435: 1 | F435: 2 | G435: L
A436: A | B436: 1 | C436: -38 | D436: -51 | E436: 13 | F436: -2 | G436: W
A437: H | B437: 7 | C437: 115 | D437: 43 | E437: 72 | F437: -1 | G437: L
A438: H | B438: 9 | C438: 148 | D438: 34 | E438: 114 | F438: 3 | G438: W
... A533: H | B533: 6 | C533: 83 | D533: -40 | E533: 123 | F533: -1 | G533: W

Sheet names
A1: Where | B1: D | C1: 2 | D1: H | E1: A
A2: 1stD Diff | B2: C | C2: -19 | D2: 19 | E2: x
A3: TotYd Diff | B3: C | C3: -443 | D3: 443 | E3: x
A4: PassY Diff | B4: C | C4: -293 | D4: 293 | E4: x
A5: RushY Diff | B5: C | C5: -263 | D5: 263 | E5: x
A6: TO Diff | B6: C | C6: -6 | D6: 6 | E6: x
A7: Outcome | B7: D | C7: 2 | D7: W | E7: L

Sheet train
A1: H | B1: 9 | C1: 259 | D1: 125 | E1: 134 | F1: -2 | G1: W
A2: A | B2: -4 | C2: -151 | D2: -158 | E2: 7 | F2: 1 | G2: L
A3: H | B3: 15 | C3: 276 | D3: 244 | E3: 32 | F3: 1 | G3: W
A4: A | B4: -2 | C4: -74 | D4: -28 | E4: -46 | F4: 0 | G4: L
A5: A | B5: 9 | C5: 157 | D5: 105 | E5: 52 | F5: -3 | G5: W
A6: H | B6: 8 | C6: 247 | D6: 11 | E6: 236 | F6: 0 | G6: W
A7: A | B7: -9 | C7: -136 | D7: -4 | E7: -132 | F7: 0 | G7: L
A8: H | B8: 3 | C8: 96 | D8: 128 | E8: -32 | F8: 0 | G8: W
A9: A | B9: 7 | C9: 2 | D9: 1 | E9: 1 | F9: 0 | G9: L
A10: H | B10: 3 | C10: 6 | D10: 24 | E10: -18 | F10: 0 | G10: W
A11: A | B11: -14 | C11: -10 | D11: 27 | E11: -37 | F11: 0 | G11: L
A12: H | B12: -10 | C12: -197 | D12: -235 | E12: 38 | F12: -2 | G12: W
... A427: H | B427: 7 | C427: 47 | D427: 33 | E427: 14 | F427: -1 | G427: W

Sheet test
A1: H | B1: -8 | C1: -134 | D1: -45 | E1: -89 | F1: -2 | G1: W
A2: A | B2: 2 | C2: -7 | D2: -28 | E2: 21 | F2: -3 | G2: W
A3: H | B3: -5 | C3: -166 | D3: -30 | E3: -136 | F3: 1 | G3: L
A4: H | B4: -2 | C4: -4 | D4: -227 | E4: 223 | F4: -3 | G4: W
A5: A | B5: 7 | C5: 116 | D5: 111 | E5: 5 | F5: 0 | G5: W
A6: A | B6: -12 | C6: -158 | D6: -56 | E6: -102 | F6: 2 | G6: L
A7: H | B7: -6 | C7: -3 | D7: -4 | E7: 1 | F7: 2 | G7: L
A8: A | B8: 1 | C8: -38 | D8: -51 | E8: 13 | F8: -2 | G8: W
A9: H | B9: 7 | C9: 115 | D9: 43 | E9: 72 | F9: -1 | G9: L
A10: H | B10: 9 | C10: 148 | D10: 34 | E10: 114 | F10: 3 | G10: W
A11: A | B11: -4 | C11: -39 | D11: -16 | E11: -23 | F11: -2 | G11: W
A12: A | B12: 3 | C12: 2 | D12: 25 | E12: -23 | F12: -4 | G12: W
... A105: H | B105: 6 | C105: 83 | D105: -40 | E105: 123 | F105: -1 | G105: W

Sheet NFLDataSetDiscrete2
A1: Where | B1: 1stD Diff | C1: TotYd Diff | D1: PassY Diff | E1: RushY Diff | F1: TO Diff | G1: Outcome
A2: H | B2: High | C2: High | D2: High | E2: High | F2: Low | G2: W
A3: A | B3: Medium | C3: Low | D3: Low | E3: Medium | F3: High | G3: L
A4: H | B4: High | C4: High | D4: High | E4: Medium | F4: High | G4: W
A5: A | B5: Medium | C5: Medium | D5: Medium | E5: Medium | F5: Medium | G5: L
A6: A | B6: High | C6: High | D6: High | E6: Medium | F6: Low | G6: W
A7: H | B7: High | C7: High | D7: Medium | E7: High | F7: Medium | G7: W
A8: A | B8: Low | C8: Low | D8: Medium | E8: Low | F8: Medium | G8: L
A9: H | B9: Medium | C9: High | D9: High | E9: Medium | F9: Medium | G9: W
A10: A | B10: High | C10: Medium | D10: Medium | E10: Medium | F10: Medium | G10: L
A11: H | B11: Medium | C11: Medium | D11: Medium | E11: Medium | F11: Medium | G11: W
A12: A | B12: Low | C12: Medium | D12: Medium | E12: Medium | F12: Medium | G12: L
... A533: H | B533: High | C533: High | D533: Medium | E533: High | F533: Medium | G533: W

Sheet NFLTrain
A1: =NFLDataSet!A2 -> H | B1: =VLOOKUP(NFLDataSet!B2,FirstDownDiff2,2,TRUE) -> High | C1: =VLOOKUP(NFLDataSet!C2,TotalYardDiff2,2,TRUE) -> High | D1: =VLOOKUP(NFLDataSet!D2,PassYardsDiff2,2,TRUE) -> High | E1: =VLOOKUP(NFLDataSet!E2,RushYards2,2,TRUE) -> High | F1: =VLOOKUP(NFLDataSet!F2,TurnOverDiff2,2,TRUE) -> Medium | G1: =NFLDataSet!G2 -> W
A2: =NFLDataSet!A3 -> A | B2: =VLOOKUP(NFLDataSet!B3,FirstDownDiff2,2,TRUE) -> Medium | C2: =VLOOKUP(NFLDataSet!C3,TotalYardDiff2,2,TRUE) -> Low | D2: =VLOOKUP(NFLDataSet!D3,PassYardsDiff2,2,TRUE) -> Low | E2: =VLOOKUP(NFLDataSet!E3,RushYards2,2,TRUE) -> Medium | F2: =VLOOKUP(NFLDataSet!F3,TurnOverDiff2,2,TRUE) -> Medium | G2: =NFLDataSet!G3 -> L
A3: =NFLDataSet!A4 -> H | B3: =VLOOKUP(NFLDataSet!B4,FirstDownDiff2,2,TRUE) -> High | C3: =VLOOKUP(NFLDataSet!C4,TotalYardDiff2,2,TRUE) -> High | D3: =VLOOKUP(NFLDataSet!D4,PassYardsDiff2,2,TRUE) -> High | E3: =VLOOKUP(NFLDataSet!E4,RushYards2,2,TRUE) -> Medium | F3: =VLOOKUP(NFLDataSet!F4,TurnOverDiff2,2,TRUE) -> Medium | G3: =NFLDataSet!G4 -> W
A4: =NFLDataSet!A5 -> A | B4: =VLOOKUP(NFLDataSet!B5,FirstDownDiff2,2,TRUE) -> Medium | C4: =VLOOKUP(NFLDataSet!C5,TotalYardDiff2,2,TRUE) -> Medium | D4: =VLOOKUP(NFLDataSet!D5,PassYardsDiff2,2,TRUE) -> Medium | E4: =VLOOKUP(NFLDataSet!E5,RushYards2,2,TRUE) -> Medium | F4: =VLOOKUP(NFLDataSet!F5,TurnOverDiff2,2,TRUE) -> Medium | G4: =NFLDataSet!G5 -> L
A5: =NFLDataSet!A6 -> A | B5: =VLOOKUP(NFLDataSet!B6,FirstDownDiff2,2,TRUE) -> High | C5: =VLOOKUP(NFLDataSet!C6,TotalYardDiff2,2,TRUE) -> High | D5: =VLOOKUP(NFLDataSet!D6,PassYardsDiff2,2,TRUE) -> High | E5: =VLOOKUP(NFLDataSet!E6,RushYards2,2,TRUE) -> Medium | F5: =VLOOKUP(NFLDataSet!F6,TurnOverDiff2,2,TRUE) -> Medium | G5: =NFLDataSet!G6 -> W
A6: =NFLDataSet!A7 -> H | B6: =VLOOKUP(NFLDataSet!B7,FirstDownDiff2,2,TRUE) -> High | C6: =VLOOKUP(NFLDataSet!C7,TotalYardDiff2,2,TRUE) -> High | D6: =VLOOKUP(NFLDataSet!D7,PassYardsDiff2,2,TRUE) -> Medium | E6: =VLOOKUP(NFLDataSet!E7,RushYards2,2,TRUE) -> High | F6: =VLOOKUP(NFLDataSet!F7,TurnOverDiff2,2,TRUE) -> Medium | G6: =NFLDataSet!G7 -> W
A7: =NFLDataSet!A8 -> A | B7: =VLOOKUP(NFLDataSet!B8,FirstDownDiff2,2,TRUE) -> Low | C7: =VLOOKUP(NFLDataSet!C8,TotalYardDiff2,2,TRUE) -> Low | D7: =VLOOKUP(NFLDataSet!D8,PassYardsDiff2,2,TRUE) -> Medium | E7: =VLOOKUP(NFLDataSet!E8,RushYards2,2,TRUE) -> Low | F7: =VLOOKUP(NFLDataSet!F8,TurnOverDiff2,2,TRUE) -> Medium | G7: =NFLDataSet!G8 -> L
A8: =NFLDataSet!A9 -> H | B8: =VLOOKUP(NFLDataSet!B9,FirstDownDiff2,2,TRUE) -> Medium | C8: =VLOOKUP(NFLDataSet!C9,TotalYardDiff2,2,TRUE) -> High | D8: =VLOOKUP(NFLDataSet!D9,PassYardsDiff2,2,TRUE) -> High | E8: =VLOOKUP(NFLDataSet!E9,RushYards2,2,TRUE) -> Medium | F8: =VLOOKUP(NFLDataSet!F9,TurnOverDiff2,2,TRUE) -> Medium | G8: =NFLDataSet!G9 -> W
A9: =NFLDataSet!A10 -> A | B9: =VLOOKUP(NFLDataSet!B10,FirstDownDiff2,2,TRUE) -> High | C9: =VLOOKUP(NFLDataSet!C10,TotalYardDiff2,2,TRUE) -> Medium | D9: =VLOOKUP(NFLDataSet!D10,PassYardsDiff2,2,TRUE) -> Medium | E9: =VLOOKUP(NFLDataSet!E10,RushYards2,2,TRUE) -> Medium | F9: =VLOOKUP(NFLDataSet!F10,TurnOverDiff2,2,TRUE) -> Medium | G9: =NFLDataSet!G10 -> L
A10: =NFLDataSet!A11 -> H | B10: =VLOOKUP(NFLDataSet!B11,FirstDownDiff2,2,TRUE) -> Medium | C10: =VLOOKUP(NFLDataSet!C11,TotalYardDiff2,2,TRUE) -> Medium | D10: =VLOOKUP(NFLDataSet!D11,PassYardsDiff2,2,TRUE) -> Medium | E10: =VLOOKUP(NFLDataSet!E11,RushYards2,2,TRUE) -> Medium | F10: =VLOOKUP(NFLDataSet!F11,TurnOverDiff2,2,TRUE) -> Medium | G10: =NFLDataSet!G11 -> W
A11: =NFLDataSet!A12 -> A | B11: =VLOOKUP(NFLDataSet!B12,FirstDownDiff2,2,TRUE) -> Low | C11: =VLOOKUP(NFLDataSet!C12,TotalYardDiff2,2,TRUE) -> Medium | D11: =VLOOKUP(NFLDataSet!D12,PassYardsDiff2,2,TRUE) -> Medium | E11: =VLOOKUP(NFLDataSet!E12,RushYards2,2,TRUE) -> Medium | F11: =VLOOKUP(NFLDataSet!F12,TurnOverDiff2,2,TRUE) -> Medium | G11: =NFLDataSet!G12 -> L
A12: =NFLDataSet!A13 -> H | B12: =VLOOKUP(NFLDataSet!B13,FirstDownDiff2,2,TRUE) -> Low | C12: =VLOOKUP(NFLDataSet!C13,TotalYardDiff2,2,TRUE) -> Low | D12: =VLOOKUP(NFLDataSet!D13,PassYardsDiff2,2,TRUE) -> Low | E12: =VLOOKUP(NFLDataSet!E13,RushYards2,2,TRUE) -> Medium | F12: =VLOOKUP(NFLDataSet!F13,TurnOverDiff2,2,TRUE) -> Medium | G12: =NFLDataSet!G13 -> W
... A426: =NFLDataSet!A427 -> A | B426: =VLOOKUP(NFLDataSet!B427,FirstDownDiff2,2,TRUE) -> High | C426: =VLOOKUP(NFLDataSet!C427,TotalYardDiff2,2,TRUE) -> High | D426: =VLOOKUP(NFLDataSet!D427,PassYardsDiff2,2,TRUE) -> High | E426: =VLOOKUP(NFLDataSet!E427,RushYards2,2,TRUE) -> High | F426: =VLOOKUP(NFLDataSet!F427,TurnOverDiff2,2,TRUE) -> High | G426: =NFLDataSet!G427 -> W

Sheet NFLTest
A1: =NFLDataSet!A427 -> A | B1: =VLOOKUP(NFLDataSet!B427,FirstDownDiff2,2,TRUE) -> High | C1: =VLOOKUP(NFLDataSet!C426,TotalYardDiff2,2,TRUE) -> Low | D1: =VLOOKUP(NFLDataSet!D426,PassYardsDiff2,2,TRUE) -> Medium | E1: =VLOOKUP(NFLDataSet!E426,RushYards2,2,TRUE) -> Low | F1: =VLOOKUP(NFLDataSet!F426,TurnOverDiff2,2,TRUE) -> Medium | G1: =NFLDataSet!G427 -> W
A2: =NFLDataSet!A428 -> H | B2: =VLOOKUP(NFLDataSet!B428,FirstDownDiff2,2,TRUE) -> High | C2: =VLOOKUP(NFLDataSet!C427,TotalYardDiff2,2,TRUE) -> High | D2: =VLOOKUP(NFLDataSet!D427,PassYardsDiff2,2,TRUE) -> High | E2: =VLOOKUP(NFLDataSet!E427,RushYards2,2,TRUE) -> High | F2: =VLOOKUP(NFLDataSet!F427,TurnOverDiff2,2,TRUE) -> High | G2: =NFLDataSet!G428 -> W
A3: =NFLDataSet!A429 -> H | B3: =VLOOKUP(NFLDataSet!B429,FirstDownDiff2,2,TRUE) -> Low | C3: =VLOOKUP(NFLDataSet!C428,TotalYardDiff2,2,TRUE) -> Medium | D3: =VLOOKUP(NFLDataSet!D428,PassYardsDiff2,2,TRUE) -> Medium | E3: =VLOOKUP(NFLDataSet!E428,RushYards2,2,TRUE) -> Medium | F3: =VLOOKUP(NFLDataSet!F428,TurnOverDiff2,2,TRUE) -> Medium | G3: =NFLDataSet!G429 -> W
A4: =NFLDataSet!A430 -> A | B4: =VLOOKUP(NFLDataSet!B430,FirstDownDiff2,2,TRUE) -> Medium | C4: =VLOOKUP(NFLDataSet!C429,TotalYardDiff2,2,TRUE) -> Low | D4: =VLOOKUP(NFLDataSet!D429,PassYardsDiff2,2,TRUE) -> Medium | E4: =VLOOKUP(NFLDataSet!E429,RushYards2,2,TRUE) -> Low | F4: =VLOOKUP(NFLDataSet!F429,TurnOverDiff2,2,TRUE) -> Medium | G4: =NFLDataSet!G430 -> W
A5: =NFLDataSet!A431 -> H | B5: =VLOOKUP(NFLDataSet!B431,FirstDownDiff2,2,TRUE) -> Medium | C5: =VLOOKUP(NFLDataSet!C430,TotalYardDiff2,2,TRUE) -> Medium | D5: =VLOOKUP(NFLDataSet!D430,PassYardsDiff2,2,TRUE) -> Medium | E5: =VLOOKUP(NFLDataSet!E430,RushYards2,2,TRUE) -> Medium | F5: =VLOOKUP(NFLDataSet!F430,TurnOverDiff2,2,TRUE) -> Medium | G5: =NFLDataSet!G431 -> L
A6: =NFLDataSet!A432 -> H | B6: =VLOOKUP(NFLDataSet!B432,FirstDownDiff2,2,TRUE) -> Medium | C6: =VLOOKUP(NFLDataSet!C431,TotalYardDiff2,2,TRUE) -> Low | D6: =VLOOKUP(NFLDataSet!D431,PassYardsDiff2,2,TRUE) -> Medium | E6: =VLOOKUP(NFLDataSet!E431,RushYards2,2,TRUE) -> Low | F6: =VLOOKUP(NFLDataSet!F431,TurnOverDiff2,2,TRUE) -> Medium | G6: =NFLDataSet!G432 -> W
A7: =NFLDataSet!A433 -> A | B7: =VLOOKUP(NFLDataSet!B433,FirstDownDiff2,2,TRUE) -> High | C7: =VLOOKUP(NFLDataSet!C432,TotalYardDiff2,2,TRUE) -> Medium | D7: =VLOOKUP(NFLDataSet!D432,PassYardsDiff2,2,TRUE) -> Low | E7: =VLOOKUP(NFLDataSet!E432,RushYards2,2,TRUE) -> High | F7: =VLOOKUP(NFLDataSet!F432,TurnOverDiff2,2,TRUE) -> Medium | G7: =NFLDataSet!G433 -> W
A8: =NFLDataSet!A434 -> A | B8: =VLOOKUP(NFLDataSet!B434,FirstDownDiff2,2,TRUE) -> Low | C8: =VLOOKUP(NFLDataSet!C433,TotalYardDiff2,2,TRUE) -> High | D8: =VLOOKUP(NFLDataSet!D433,PassYardsDiff2,2,TRUE) -> High | E8: =VLOOKUP(NFLDataSet!E433,RushYards2,2,TRUE) -> Medium | F8: =VLOOKUP(NFLDataSet!F433,TurnOverDiff2,2,TRUE) -> Medium | G8: =NFLDataSet!G434 -> L
A9: =NFLDataSet!A435 -> H | B9: =VLOOKUP(NFLDataSet!B435,FirstDownDiff2,2,TRUE) -> Low | C9: =VLOOKUP(NFLDataSet!C434,TotalYardDiff2,2,TRUE) -> Low | D9: =VLOOKUP(NFLDataSet!D434,PassYardsDiff2,2,TRUE) -> Medium | E9: =VLOOKUP(NFLDataSet!E434,RushYards2,2,TRUE) -> Low | F9: =VLOOKUP(NFLDataSet!F434,TurnOverDiff2,2,TRUE) -> Medium | G9: =NFLDataSet!G435 -> L
A10: =NFLDataSet!A436 -> A | B10: =VLOOKUP(NFLDataSet!B436,FirstDownDiff2,2,TRUE) -> Medium | C10: =VLOOKUP(NFLDataSet!C435,TotalYardDiff2,2,TRUE) -> Medium | D10: =VLOOKUP(NFLDataSet!D435,PassYardsDiff2,2,TRUE) -> Medium | E10: =VLOOKUP(NFLDataSet!E435,RushYards2,2,TRUE) -> Medium | F10: =VLOOKUP(NFLDataSet!F435,TurnOverDiff2,2,TRUE) -> Medium | G10: =NFLDataSet!G436 -> W
A11: =NFLDataSet!A437 -> H | B11: =VLOOKUP(NFLDataSet!B437,FirstDownDiff2,2,TRUE) -> High | C11: =VLOOKUP(NFLDataSet!C436,TotalYardDiff2,2,TRUE) -> Medium | D11: =VLOOKUP(NFLDataSet!D436,PassYardsDiff2,2,TRUE) -> Medium | E11: =VLOOKUP(NFLDataSet!E436,RushYards2,2,TRUE) -> Medium | F11: =VLOOKUP(NFLDataSet!F436,TurnOverDiff2,2,TRUE) -> Medium | G11: =NFLDataSet!G437 -> L
A12: =NFLDataSet!A438 -> H | B12: =VLOOKUP(NFLDataSet!B438,FirstDownDiff2,2,TRUE) -> High | C12: =VLOOKUP(NFLDataSet!C437,TotalYardDiff2,2,TRUE) -> High | D12: =VLOOKUP(NFLDataSet!D437,PassYardsDiff2,2,TRUE) -> Medium | E12: =VLOOKUP(NFLDataSet!E437,RushYards2,2,TRUE) -> High | F12: =VLOOKUP(NFLDataSet!F437,TurnOverDiff2,2,TRUE) -> Medium | G12: =NFLDataSet!G438 -> W
... A54: =NFLDataSet!A480 -> H | B54: =VLOOKUP(NFLDataSet!B480,FirstDownDiff2,2,TRUE) -> High | C54: =VLOOKUP(NFLDataSet!C479,TotalYardDiff2,2,TRUE) -> High | D54: =VLOOKUP(NFLDataSet!D479,PassYardsDiff2,2,TRUE) -> High | E54: =VLOOKUP(NFLDataSet!E479,RushYards2,2,TRUE) -> Medium | F54: =VLOOKUP(NFLDataSet!F479,TurnOverDiff2,2,TRUE) -> High | G54: =NFLDataSet!G480 -> W

Sheet NFLValidation
A1: =NFLDataSet!A481 -> A | B1: =VLOOKUP(NFLDataSet!B481,FirstDownDiff2,2,TRUE) -> High | C1: =VLOOKUP(NFLDataSet!C481,TotalYardDiff2,2,TRUE) -> Medium | D1: =VLOOKUP(NFLDataSet!D481,PassYardsDiff2,2,TRUE) -> High | E1: =VLOOKUP(NFLDataSet!E481,RushYards2,2,TRUE) -> Low | F1: =VLOOKUP(NFLDataSet!F481,TurnOverDiff2,2,TRUE) -> Medium | G1: =NFLDataSet!G481 -> W
A2: =NFLDataSet!A482 -> H | B2: =VLOOKUP(NFLDataSet!B482,FirstDownDiff2,2,TRUE) -> Medium | C2: =VLOOKUP(NFLDataSet!C482,TotalYardDiff2,2,TRUE) -> Medium | D2: =VLOOKUP(NFLDataSet!D482,PassYardsDiff2,2,TRUE) -> Medium | E2: =VLOOKUP(NFLDataSet!E482,RushYards2,2,TRUE) -> Medium | F2: =VLOOKUP(NFLDataSet!F482,TurnOverDiff2,2,TRUE) -> Medium | G2: =NFLDataSet!G482 -> W
A3: =NFLDataSet!A483 -> A | B3: =VLOOKUP(NFLDataSet!B483,FirstDownDiff2,2,TRUE) -> High | C3: =VLOOKUP(NFLDataSet!C483,TotalYardDiff2,2,TRUE) -> High | D3: =VLOOKUP(NFLDataSet!D483,PassYardsDiff2,2,TRUE) -> High | E3: =VLOOKUP(NFLDataSet!E483,RushYards2,2,TRUE) -> Low | F3: =VLOOKUP(NFLDataSet!F483,TurnOverDiff2,2,TRUE) -> Medium | G3: =NFLDataSet!G483 -> L
A4: =NFLDataSet!A484 -> A | B4: =VLOOKUP(NFLDataSet!B484,FirstDownDiff2,2,TRUE) -> High | C4: =VLOOKUP(NFLDataSet!C484,TotalYardDiff2,2,TRUE) -> High | D4: =VLOOKUP(NFLDataSet!D484,PassYardsDiff2,2,TRUE) -> High | E4: =VLOOKUP(NFLDataSet!E484,RushYards2,2,TRUE) -> High | F4: =VLOOKUP(NFLDataSet!F484,TurnOverDiff2,2,TRUE) -> Medium | G4: =NFLDataSet!G484 -> W
A5: =NFLDataSet!A485 -> H | B5: =VLOOKUP(NFLDataSet!B485,FirstDownDiff2,2,TRUE) -> Low | C5: =VLOOKUP(NFLDataSet!C485,TotalYardDiff2,2,TRUE) -> Medium | D5: =VLOOKUP(NFLDataSet!D485,PassYardsDiff2,2,TRUE) -> Low | E5: =VLOOKUP(NFLDataSet!E485,RushYards2,2,TRUE) -> High | F5: =VLOOKUP(NFLDataSet!F485,TurnOverDiff2,2,TRUE) -> Medium | G5: =NFLDataSet!G485 -> L
A6: =NFLDataSet!A486 -> H | B6: =VLOOKUP(NFLDataSet!B486,FirstDownDiff2,2,TRUE) -> Medium | C6: =VLOOKUP(NFLDataSet!C486,TotalYardDiff2,2,TRUE) -> High | D6: =VLOOKUP(NFLDataSet!D486,PassYardsDiff2,2,TRUE) -> High | E6: =VLOOKUP(NFLDataSet!E486,RushYards2,2,TRUE) -> Medium | F6: =VLOOKUP(NFLDataSet!F486,TurnOverDiff2,2,TRUE) -> Medium | G6: =NFLDataSet!G486 -> W
A7: =NFLDataSet!A487 -> H | B7: =VLOOKUP(NFLDataSet!B487,FirstDownDiff2,2,TRUE) -> Medium | C7: =VLOOKUP(NFLDataSet!C487,TotalYardDiff2,2,TRUE) -> Low | D7: =VLOOKUP(NFLDataSet!D487,PassYardsDiff2,2,TRUE) -> Medium | E7: =VLOOKUP(NFLDataSet!E487,RushYards2,2,TRUE) -> Low | F7: =VLOOKUP(NFLDataSet!F487,TurnOverDiff2,2,TRUE) -> Medium | G7: =NFLDataSet!G487 -> L
A8: =NFLDataSet!A488 -> H | B8: =VLOOKUP(NFLDataSet!B488,FirstDownDiff2,2,TRUE) -> High | C8: =VLOOKUP(NFLDataSet!C488,TotalYardDiff2,2,TRUE) -> High | D8: =VLOOKUP(NFLDataSet!D488,PassYardsDiff2,2,TRUE) -> High | E8: =VLOOKUP(NFLDataSet!E488,RushYards2,2,TRUE) -> High | F8: =VLOOKUP(NFLDataSet!F488,TurnOverDiff2,2,TRUE) -> Medium | G8: =NFLDataSet!G488 -> W
A9: =NFLDataSet!A489 -> H | B9: =VLOOKUP(NFLDataSet!B489,FirstDownDiff2,2,TRUE) -> High | C9: =VLOOKUP(NFLDataSet!C489,TotalYardDiff2,2,TRUE) -> Medium | D9: =VLOOKUP(NFLDataSet!D489,PassYardsDiff2,2,TRUE) -> Medium | E9: =VLOOKUP(NFLDataSet!E489,RushYards2,2,TRUE) -> Low | F9: =VLOOKUP(NFLDataSet!F489,TurnOverDiff2,2,TRUE) -> High | G9: =NFLDataSet!G489 -> L
A10: =NFLDataSet!A490 -> A | B10: =VLOOKUP(NFLDataSet!B490,FirstDownDiff2,2,TRUE) -> Low | C10: =VLOOKUP(NFLDataSet!C490,TotalYardDiff2,2,TRUE) -> Medium | D10: =VLOOKUP(NFLDataSet!D490,PassYardsDiff2,2,TRUE) -> Medium | E10: =VLOOKUP(NFLDataSet!E490,RushYards2,2,TRUE) -> Medium | F10: =VLOOKUP(NFLDataSet!F490,TurnOverDiff2,2,TRUE) -> Medium | G10: =NFLDataSet!G490 -> L
A11: =NFLDataSet!A491 -> A | B11: =VLOOKUP(NFLDataSet!B491,FirstDownDiff2,2,TRUE) -> Medium | C11: =VLOOKUP(NFLDataSet!C491,TotalYardDiff2,2,TRUE) -> Medium | D11: =VLOOKUP(NFLDataSet!D491,PassYardsDiff2,2,TRUE) -> High | E11: =VLOOKUP(NFLDataSet!E491,RushYards2,2,TRUE) -> Low | F11: =VLOOKUP(NFLDataSet!F491,TurnOverDiff2,2,TRUE) -> High | G11: =NFLDataSet!G491 -> L
A12: =NFLDataSet!A492 -> A | B12: =VLOOKUP(NFLDataSet!B492,FirstDownDiff2,2,TRUE) -> Medium | C12: =VLOOKUP(NFLDataSet!C492,TotalYardDiff2,2,TRUE) -> Medium | D12: =VLOOKUP(NFLDataSet!D492,PassYardsDiff2,2,TRUE) -> High | E12: =VLOOKUP(NFLDataSet!E492,RushYards2,2,TRUE) -> Low | F12: =VLOOKUP(NFLDataSet!F492,TurnOverDiff2,2,TRUE) -> Medium | G12: =NFLDataSet!G492 -> L
... A53: =NFLDataSet!A533 -> H | B53: =VLOOKUP(NFLDataSet!B533,FirstDownDiff2,2,TRUE) -> High | C53: =VLOOKUP(NFLDataSet!C533,TotalYardDiff2,2,TRUE) -> High | D53: =VLOOKUP(NFLDataSet!D533,PassYardsDiff2,2,TRUE) -> Medium | E53: =VLOOKUP(NFLDataSet!E533,RushYards2,2,TRUE) -> High | F53: =VLOOKUP(NFLDataSet!F533,TurnOverDiff2,2,TRUE) -> Medium | G53: =NFLDataSet!G533 -> W

Sheet Reference2
C1: 1stD Diff | D1: TotYd Diff | E1: PassY Diff | F1: RushY Diff | G1: TO Diff
A2: Low | B2: Min | C2: -19 | D2: -443 | E2: -293 | F2: -263 | G2: -6
A3: Medium | B3: Q2 | C3: 0 | D3: 0 | E3: 0 | F3: 0 | G3: 0
A4: High | B4: Max | C4: 19 | D4: 443 | E4: 293 | F4: 263 | G4: 6
A6: -500 | B6: Low | D6: -500 | E6: Low | G6: -500 | H6: Low | J6: -500 | K6: Low | M6: -500 | N6: Low
A7: -5.75 | B7: Medium | D7: -78.75 | E7: Medium | G7: -71 | H7: Medium | J7: -54 | K7: Medium | M7: -3 | N7: Medium
A8: 5.75 | B8: High | D8: 78.75 | E8: High | G8: 71 | H8: High | J8: 54 | K8: High | M8: 3 | N8: High
A9: 19 | D9: 443 | G9: 293 | J9: 263 | M9: 6
A12: -500 | B12: Low | D12: -500 | E12: Low | G12: -500 | H12: Low | J12: -500 | K12: Low | M12: -500 | N12: Low
A13: -5.75 | B13: Medium | D13: -78.75 | E13: Medium | G13: -71 | H13: Medium | J13: -54 | K13: Medium | M13: -1 | N13: Medium | P13: 79
A14: 5.75 | B14: High | D14: 78.75 | E14: High | G14: 71 | H14: High | J14: 54 | K14: High | M14: 1 | N14: High
A15: 19 | D15: 443 | G15: 293 | J15: 263 | M15: 6
A17: -500 | B17: Low | D17: -500 | E17: Low | G17: -500 | H17: Low | J17: -500 | K17: Low | M17: -500 | N17: Low
A18: -5 | B18: Medium | D18: -70 | E18: Medium | G18: -65 | H18: Medium | J18: -50 | K18: Medium | M18: -2 | N18: Medium | P18: 77
A19: 5 | B19: High | D19: 70 | E19: High | G19: 65 | H19: High | J19: 50 | K19: High | M19: 2 | N19: High
A20: 19 | D20: 443 | G20: 293 | J20: 263 | M20: 6
A22: -500 | B22: Low | D22: -500 | E22: Low | G22: -500 | H22: Low | J22: -500 | K22: Low | M22: -500 | N22: Low
A23: -6 | B23: Medium | D23: -80 | E23: Medium | G23: -75 | H23: Medium | J23: -60 | K23: Medium | M23: -0.5 | N23: Medium | P23: 73
A24: 6 | B24: High | D24: 80 | E24: High | G24: 75 | H24: High | J24: 60 | K24: High | M24: 0.5 | N24: High
A25: 19 | D25: 443 | G25: 293 | J25: 263 | M25: 6
A27: -500 | B27: Low | D27: -500 | E27: Low | G27: -500 | H27: Low | J27: -500 | K27: Low | M27: -500 | N27: Low
A28: -5.4 | B28: Medium | D28: -74 | E28: Medium | G28: -68 | H28: Medium | J28: -52 | K28: Medium | M28: -1.5 | N28: Medium | P28: 77
A29: 5.4 | B29: High | D29: 74 | E29: High | G29: 68 | H29: High | J29: 52 | K29: High | M29: 1.5 | N29: High
A30: 19 | D30: 443 | G30: 293 | J30: 263 | M30: 6
A32: -500 | B32: Low | D32: -500 | E32: Low | G32: -500 | H32: Low | J32: -500 | K32: Low | M32: -500 | N32: Low
A33: -5.6 | B33: Medium | D33: -77 | E33: Medium | G33: -70 | H33: Medium | J33: -54 | K33: Medium | M33: -1 | N33: Medium | P33: 79
A34: 5.6 | B34: High | D34: 77 | E34: High | G34: 70 | H34: High | J34: 54 | K34: High | M34: 1 | N34: High
A35: 19 | D35: 443 | G35: 293 | J35: 263 | M35: 6
A37: -500 | B37: Low | D37: -500 | E37: Low | G37: -500 | H37: Low | J37: -500 | K37: Low | M37: -500 | N37: Low | P37: 79.2
A38: -5.75 | B38: Medium | D38: -70 | E38: Medium | G38: -71 | H38: Medium | J38: -54 | K38: Medium | M38: -1 | N38: Medium
A39: 5.75 | B39: High | D39: 70 | E39: High | G39: 71 | H39: High | J39: 54 | K39: High | M39: 1 | N39: High
A40: 19 | D40: 443 | G40: 293 | J40: 263 | M40: 6
A42: -500 | B42: Low | D42: -500 | E42: Low | G42: -500 | H42: Low | J42: -500 | K42: Low | M42: -500 | N42: Low
A43: -6.75 | B43: Medium | D43: -78.75 | E43: Medium | G43: -71 | H43: Medium | J43: -54 | K43: Medium | M43: -1 | N43: Medium | P43: 79.2
A44: 6.75 | B44: High | D44: 78.75 | E44: High | G44: 71 | H44: High | J44: 54 | K44: High | M44: 1 | N44: High
A45: 19 | D45: 443 | G45: 293 | J45: 263 | M45: 6
A47: -500 | B47: Low | D47: -500 | E47: Low | G47: -500 | H47: Low | J47: -500 | K47: Low | M47: -500 | N47: Low
A48: -5.75 | B48: Medium | D48: -78.75 | E48: Medium | G48: -71 | H48: Medium | J48: -54 | K48: Medium | M48: -3 | N48: Medium | P48: 77
A49: 5.75 | B49: High | D49: 78.75 | E49: High | G49: 71 | H49: High | J49: 54 | K49: High | M49: 3 | N49: High
A50: 19 | D50: 443 | G50: 293 | J50: 263 | M50: 6

Sheet NFLDataSetDiscrete
A1: Where | B1: 1stD Diff | C1: TotYd Diff | D1: PassY Diff | E1: RushY Diff | F1: TO Diff | G1: Outcome
A2: H | B2: High | C2: High | D2: High | E2: High | F2: MediumLow | G2: W
A3: A | B3: Medium | C3: MediumLow | D3: MediumLow | E3: MediumHigh | F3: High | G3: L
A4: H | B4: High | C4: High | D4: High | E4: MediumHigh | F4: High | G4: W
A5: A | B5: Medium | C5: Medium | D5: Medium | E5: Medium | F5: MediumHigh | G5: L
A6: A | B6: High | C6: High | D6: High | E6: MediumHigh | F6: MediumLow | G6: W
A7: H | B7: High | C7: High | D7: MediumHigh | E7: High | F7: MediumHigh | G7: W
A8: A | B8: MediumLow | C8: MediumLow | D8: Medium | E8: MediumLow | F8: MediumHigh | G8: L
A9: H | B9: MediumHigh | C9: High | D9: High | E9: Medium | F9: MediumHigh | G9: W
A10: A | B10: High | C10: MediumHigh | D10: MediumHigh | E10: MediumHigh | F10: MediumHigh | G10: L
A11: H | B11: MediumHigh | C11: MediumHigh | D11: MediumHigh | E11: Medium | F11: MediumHigh | G11: W
A12: A | B12: MediumLow | C12: Medium | D12: MediumHigh | E12: Medium | F12: MediumHigh | G12: L
... A533: H | B533: High | C533: High | D533: Medium | E533: High | F533: Medium | G533: W

Sheet Reference
C1: 1stD Diff | D1: TotYd Diff | E1: PassY Diff | F1: RushY Diff | G1: TO Diff
A2: Low | B2: Min | C2: -19 | D2: -443 | E2: -293 | F2: -263 | G2: -6
A3: MediumLow | B3: Q1 | C3: -5.75 | D3: -78.75 | E3: -71 | F3: -54 | G3: -1
A4: Medium | B4: Q2 | C4: 0 | D4: 0 | E4: 0 | F4: 0 | G4: 0
A5: MediumHigh | B5: Q3 | C5: 5.75 | D5: 78.75 | E5: 71 | F5: 54 | G5: 1
A6: High | B6: Max | C6: 19 | D6: 443 | E6: 293 | F6: 263 | G6: 6
A8: -500 | B8: Low | D8: -500 | E8: Low | G8: -500 | H8: Low | J8: -500 | K8: Low | M8: -500 | N8: Low
A9: -19 | B9: MediumLow | D9: -443 | E9: MediumLow | G9: -293 | H9: MediumLow | J9: -263 | K9: MediumLow | M9: -6 | N9: MediumLow
A10: -5.75 | B10: Medium | D10: -78.75 | E10: Medium | G10: -71 | H10: Medium | J10: -54 | K10: Medium | M10: -1 | N10: Medium
A11: 0 | B11: MediumHigh | D11: 0 | E11: MediumHigh | G11: 0 | H11: MediumHigh | J11: 0 | K11: MediumHigh | M11: 0 | N11: MediumHigh
A12: 5.75 | B12: High | D12: 78.75 | E12: High | G12: 71 | H12: High | J12: 54 | K12: High | M12: 1 | N12: High
A13: 19 | D13: 443 | G13: 293 | J13: 263 | M13: 6
